<?xml version="1.0" encoding="utf-8"?>

<robot name="racecar" xmlns:xacro="http://www.ros.org/wiki/xacro">

    <xacro:include filename="$(find racecar_description)/urdf/macros.xacro" />
    
    <link name="base_footprint">
    </link>

    <link name="base_link">
        <visual>
            <geometry>
                <box size="2.8 1.0 0.3"/>
            </geometry>
            <origin xyz="0 0 0" rpy="0 0 0" />
            <material name="yellow">
                <color rgba="0.8 0.3 0.1 0.5" />
            </material>
        </visual>
        <collision>
            <geometry>
                <box size="2.8 1.0 0.3" />
            </geometry>
            <origin xyz="0.0 0.0 0.0" rpy="0.0 0.0 0.0" />
        </collision>
        <inertial>
            <origin xyz="0 0 0" />
            <mass value="4" />
            <inertia ixx="264" ixy="0" ixz="0" iyy="294" iyz="0" izz="36.4" />
        </inertial>

    </link>

    <joint name="base_link2base_footprint" type="fixed">
        <parent link="base_footprint" />
        <child link="base_link"/>
        <origin xyz="0 0 0.32" />
    </joint>




       <link name="left_steering_hinge">
        <visual>
            <geometry>
                <cylinder radius="0.1" length="0.05" />
                <!-- <sphere radius="0.015" /> -->
            </geometry>
            <origin xyz="0 0 0" rpy="1.57 0 0" />
            <material name="black">
                <color rgba="0.0 0.0 0.0 1.0" />
            </material>
        </visual>
        <collision>
            <geometry>
                <cylinder radius="0.1" length="0.05" />
                <!-- <sphere radius="0.015" /> -->
            </geometry>
            <origin xyz="0.0 0.0 0.0" rpy="1.57 0.0 0.0" />
        </collision>
        <inertial>
            <origin xyz="0 0 0" />
            <mass value="1" />
            <inertia ixx="2.7E-02" ixy="0" ixz="0" iyy="2.7E-02" iyz="0" izz="5E-02" />
        </inertial>
    </link>


    <joint name="left_steering_hinge_joint" type="revolute">
        <parent link="base_link" />
        <child link="left_steering_hinge" />
        <origin xyz="1.3 0.65 0" />
        <axis xyz="0 0 1" />
        <limit lower="-0.6" upper="0.6" effort="5" velocity="100.0"/>
    </joint>



    <link name="left_front_wheel">
        <visual>
            <geometry>
                <cylinder radius="0.33" length="0.2" />
            </geometry>
            <origin xyz="0 0 0" rpy="1.57 0 0" />
            <material name="black">
                <color rgba="0.0 0.0 0.0 1.0" />
            </material>
        </visual>
        <collision>
            <geometry>
                <cylinder radius="0.32" length="0.2" />
            </geometry>
            <origin xyz="0.0 0.0 0.0" rpy="1.57 0.0 0.0" />
        </collision>
        <inertial>
            <origin xyz="0 0 0" />
            <mass value="2" />
            <inertia ixx="6.64E-01" ixy="0" ixz="0" iyy="6.64E-01" iyz="0" izz="1.02E+00" />
        </inertial>
    </link>

    <joint name="left_front_wheel_joint" type="continuous">
        <parent link="left_steering_hinge" />
        <child link="left_front_wheel" />
        <origin xyz="0 0.25 0" />
        <axis xyz="0 1 0" />
        <limit effort="10" velocity="1000" />
    </joint>


<link name="right_steering_hinge">
        <visual>
            <geometry>
                 <cylinder radius="0.1" length="0.05" />
            </geometry>
            <origin xyz="0 0 0" rpy="1.57 0 0" />
            <material name="black">
                <color rgba="0.0 0.0 0.0 1.0" />
            </material>
        </visual>
        <collision>
            <geometry>
                <cylinder radius="0.1" length="0.05" />
            </geometry>
            <origin xyz="0.0 0.0 0.0" rpy="1.57 0.0 0.0" />
        </collision>
        <inertial>
            <origin xyz="0 0 0" />
            <mass value="1" />
            <inertia ixx="2.7E-02" ixy="0" ixz="0" iyy="2.7E-02" iyz="0" izz="5E-02" />
        </inertial>
    </link>

    <joint name="right_steering_hinge_joint" type="revolute">
        <parent link="base_link" />
        <child link="right_steering_hinge" />
        <origin xyz="1.3 -0.65 0" />
        <axis xyz="0 0 1" />
        <limit lower="-0.6" upper="0.6" effort="5" velocity="100.0"/>
    </joint>


     <link name="right_front_wheel">
        <visual>
            <geometry>
                <cylinder radius="0.33" length="0.2" />
            </geometry>
            <origin xyz="0 0 0" rpy="1.57 0 0" />
            <material name="black">
                <color rgba="0.0 0.0 0.0 1.0" />
            </material>
        </visual>
        <collision>
            <geometry>
                <cylinder radius="0.32" length="0.2" />
            </geometry>
            <origin xyz="0.0 0.0 0.0" rpy="1.57 0.0 0.0" />
        </collision>
        <inertial>
            <origin xyz="0 0 0" />
            <mass value="2" />
            <inertia ixx="6.64E-01" ixy="0" ixz="0" iyy="6.64E-01" iyz="0" izz="1.02E+00" />
        </inertial>
    </link>

    <joint name="right_front_wheel_joint" type="continuous">
        <parent link="right_steering_hinge" />
        <child link="right_front_wheel" />
        <origin xyz="0 -0.25 0" />
        <axis xyz="0 1 0" />
        <limit effort="10" velocity="1000" />
    </joint>




    <link name="left_rear_wheel">
        <visual>
            <geometry>
                <cylinder radius="0.32" length="0.2" />
            </geometry>
            <origin xyz="0 0 0" rpy="1.57 0 0" />
            <material name="black">
                <color rgba="0.0 0.0 0.0 1.0" />
            </material>
        </visual>
        <collision>
            <geometry>
                <cylinder radius="0.32" length="0.2" />
            </geometry>
            <origin xyz="0.0 0.0 0.0" rpy="1.57 0.0 0.0" />
        </collision>
        <inertial>
            <origin xyz="0 0 0" />
            <mass value="2" />
            <inertia ixx="6.64E-01" ixy="0" ixz="0" iyy="6.64E-01" iyz="0" izz="1.02E+00" />
        </inertial>
    </link>

    <joint name="left_rear_wheel_joint" type="continuous">
        <parent link="base_link" />
        <child link="left_rear_wheel" />
        <origin xyz="-1.3 0.9 0" />
        <axis xyz="0 1 0" />
        <limit effort="10" velocity="1000" />
    </joint>




    <link name="right_rear_wheel">
        <visual>
            <geometry>
                <cylinder radius="0.32" length="0.2" />
            </geometry>
            <origin xyz="0 0 0" rpy="1.57 0 0" />
            <material name="black">
                <color rgba="0.0 0.0 0.0 1.0" />
            </material>
        </visual>
        <collision>
            <geometry>
                <cylinder radius="0.32" length="0.2" />
            </geometry>
            <origin xyz="0.0 0.0 0.0" rpy="1.57 0.0 0.0" />
        </collision>
        <inertial>
            <origin xyz="0 0 0" />
            <mass value="2" />
            <inertia ixx="6.64E-01" ixy="0" ixz="0" iyy="6.64E-01" iyz="0" izz="1.02E+00" />
        </inertial>
    </link>

    <joint name="right_rear_wheel_joint" type="continuous">
        <parent link="base_link" />
        <child link="right_rear_wheel" />
        <origin xyz="-1.3 -0.9 0" />
        <axis xyz="0 1 0" />
        <limit effort="10" velocity="1000" />
    </joint>

  <xacro:include filename="$(find racecar_description)/urdf/racecar.gazebo" />

</robot>