<sdf version='1.7'>
  <world name='default'>
    <light name='sun' type='directional'>
      <cast_shadows>1</cast_shadows>
      <pose>0 0 10 0 -0 0</pose>
      <diffuse>0.8 0.8 0.8 1</diffuse>
      <specular>0.2 0.2 0.2 1</specular>
      <attenuation>
        <range>1000</range>
        <constant>0.9</constant>
        <linear>0.01</linear>
        <quadratic>0.001</quadratic>
      </attenuation>
      <direction>-0.5 0.1 -0.9</direction>
      <spot>
        <inner_angle>0</inner_angle>
        <outer_angle>0</outer_angle>
        <falloff>0</falloff>
      </spot>
    </light>
    <model name='ground_plane'>
      <static>1</static>
      <link name='link'>
        <collision name='collision'>
          <geometry>
            <plane>
              <normal>0 0 1</normal>
              <size>100 100</size>
            </plane>
          </geometry>
          <surface>
            <friction>
              <ode>
                <mu>100</mu>
                <mu2>50</mu2>
              </ode>
              <torsional>
                <ode/>
              </torsional>
            </friction>
            <contact>
              <ode/>
            </contact>
            <bounce/>
          </surface>
          <max_contacts>10</max_contacts>
        </collision>
        <visual name='visual'>
          <cast_shadows>0</cast_shadows>
          <geometry>
            <plane>
              <normal>0 0 1</normal>
              <size>100 100</size>
            </plane>
          </geometry>
          <material>
            <script>
              <uri>file://media/materials/scripts/gazebo.material</uri>
              <name>Gazebo/Grey</name>
            </script>
          </material>
        </visual>
        <self_collide>0</self_collide>
        <enable_wind>0</enable_wind>
        <kinematic>0</kinematic>
      </link>
    </model>
    <gravity>0 0 -9.8</gravity>
    <magnetic_field>6e-06 2.3e-05 -4.2e-05</magnetic_field>
    <atmosphere type='adiabatic'/>
    <physics type='ode'>
      <max_step_size>0.001</max_step_size>
      <real_time_factor>1</real_time_factor>
      <real_time_update_rate>1000</real_time_update_rate>
    </physics>
    <scene>
      <ambient>0.4 0.4 0.4 1</ambient>
      <background>0.7 0.7 0.7 1</background>
      <shadows>1</shadows>
    </scene>
    <wind/>
    <spherical_coordinates>
      <surface_model>EARTH_WGS84</surface_model>
      <latitude_deg>0</latitude_deg>
      <longitude_deg>0</longitude_deg>
      <elevation>0</elevation>
      <heading_deg>0</heading_deg>
    </spherical_coordinates>
    <model name='racecar'>
      <link name='base_footprint'>
        <inertial>
          <pose>0 0 0.32 0 -0 0</pose>
          <mass>4</mass>
          <inertia>
            <ixx>264</ixx>
            <ixy>0</ixy>
            <ixz>0</ixz>
            <iyy>294</iyy>
            <iyz>0</iyz>
            <izz>36.4</izz>
          </inertia>
        </inertial>
        <collision name='base_footprint_fixed_joint_lump__base_link_collision'>
          <pose>0 0 0.32 0 -0 0</pose>
          <geometry>
            <box>
              <size>2.8 1 0.3</size>
            </box>
          </geometry>
          <surface>
            <contact>
              <ode>
                <kp>100000</kp>
                <kd>5</kd>
              </ode>
            </contact>
            <friction>
              <ode>
                <mu>1</mu>
                <mu2>1</mu2>
              </ode>
              <torsional>
                <ode/>
              </torsional>
            </friction>
            <bounce/>
          </surface>
          <max_contacts>10</max_contacts>
        </collision>
        <visual name='base_footprint_fixed_joint_lump__base_link_visual'>
          <pose>0 0 0.32 0 -0 0</pose>
          <geometry>
            <box>
              <size>2.8 1 0.3</size>
            </box>
          </geometry>
          <material>
            <script>
              <name>Gazebo/Red</name>
              <uri>file://media/materials/scripts/gazebo.material</uri>
            </script>
          </material>
        </visual>
        <self_collide>0</self_collide>
        <enable_wind>0</enable_wind>
        <kinematic>0</kinematic>
      </link>
      <joint name='left_rear_wheel_joint' type='revolute'>
        <pose relative_to='base_footprint'>-1.3 0.9 0.32 0 -0 0</pose>
        <parent>base_footprint</parent>
        <child>left_rear_wheel</child>
        <axis>
          <xyz>0 1 0</xyz>
          <limit>
            <effort>10</effort>
            <velocity>1000</velocity>
            <lower>-1e+16</lower>
            <upper>1e+16</upper>
          </limit>
          <dynamics>
            <spring_reference>0</spring_reference>
            <spring_stiffness>0</spring_stiffness>
          </dynamics>
        </axis>
      </joint>
      <link name='left_rear_wheel'>
        <pose relative_to='left_rear_wheel_joint'>0 0 0 0 -0 0</pose>
        <inertial>
          <pose>0 0 0 0 -0 0</pose>
          <mass>2</mass>
          <inertia>
            <ixx>0.664</ixx>
            <ixy>0</ixy>
            <ixz>0</ixz>
            <iyy>0.664</iyy>
            <iyz>0</iyz>
            <izz>1.02</izz>
          </inertia>
        </inertial>
        <collision name='left_rear_wheel_collision'>
          <pose>0 0 0 1.57 -0 0</pose>
          <geometry>
            <cylinder>
              <length>0.2</length>
              <radius>0.32</radius>
            </cylinder>
          </geometry>
          <surface>
            <contact>
              <ode>
                <kp>100000</kp>
                <kd>5</kd>
              </ode>
            </contact>
            <friction>
              <ode>
                <mu>2</mu>
                <mu2>2</mu2>
                <fdir1>1 0 0</fdir1>
              </ode>
              <torsional>
                <ode/>
              </torsional>
            </friction>
            <bounce/>
          </surface>
          <max_contacts>10</max_contacts>
        </collision>
        <visual name='left_rear_wheel_visual'>
          <pose>0 0 0 1.57 -0 0</pose>
          <geometry>
            <cylinder>
              <length>0.2</length>
              <radius>0.32</radius>
            </cylinder>
          </geometry>
          <material>
            <script>
              <name>Gazebo/Black</name>
              <uri>file://media/materials/scripts/gazebo.material</uri>
            </script>
          </material>
        </visual>
        <self_collide>0</self_collide>
        <enable_wind>0</enable_wind>
        <kinematic>0</kinematic>
      </link>
      <joint name='left_steering_hinge_joint' type='revolute'>
        <pose relative_to='base_footprint'>1.3 0.65 0.32 0 -0 0</pose>
        <parent>base_footprint</parent>
        <child>left_steering_hinge</child>
        <axis>
          <xyz>0 0 1</xyz>
          <limit>
            <lower>-0.6</lower>
            <upper>0.6</upper>
            <effort>5</effort>
            <velocity>100</velocity>
          </limit>
          <dynamics>
            <spring_reference>0</spring_reference>
            <spring_stiffness>0</spring_stiffness>
          </dynamics>
        </axis>
      </joint>
      <link name='left_steering_hinge'>
        <pose relative_to='left_steering_hinge_joint'>0 0 0 0 -0 0</pose>
        <inertial>
          <pose>0 0 0 0 -0 0</pose>
          <mass>1</mass>
          <inertia>
            <ixx>0.027</ixx>
            <ixy>0</ixy>
            <ixz>0</ixz>
            <iyy>0.027</iyy>
            <iyz>0</iyz>
            <izz>0.05</izz>
          </inertia>
        </inertial>
        <collision name='left_steering_hinge_collision'>
          <pose>0 0 0 1.57 -0 0</pose>
          <geometry>
            <cylinder>
              <length>0.05</length>
              <radius>0.1</radius>
            </cylinder>
          </geometry>
          <surface>
            <contact>
              <ode>
                <kp>100000</kp>
                <kd>5</kd>
              </ode>
            </contact>
            <friction>
              <ode>
                <mu>1</mu>
                <mu2>1</mu2>
                <fdir1>1 0 0</fdir1>
              </ode>
              <torsional>
                <ode/>
              </torsional>
            </friction>
            <bounce/>
          </surface>
          <max_contacts>10</max_contacts>
        </collision>
        <visual name='left_steering_hinge_visual'>
          <pose>0 0 0 1.57 -0 0</pose>
          <geometry>
            <cylinder>
              <length>0.05</length>
              <radius>0.1</radius>
            </cylinder>
          </geometry>
          <material>
            <script>
              <name>Gazebo/Black</name>
              <uri>file://media/materials/scripts/gazebo.material</uri>
            </script>
          </material>
        </visual>
        <self_collide>0</self_collide>
        <enable_wind>0</enable_wind>
        <kinematic>0</kinematic>
      </link>
      <joint name='left_front_wheel_joint' type='revolute'>
        <pose relative_to='left_steering_hinge'>0 0.25 0 0 -0 0</pose>
        <parent>left_steering_hinge</parent>
        <child>left_front_wheel</child>
        <axis>
          <xyz>0 1 0</xyz>
          <limit>
            <effort>10</effort>
            <velocity>1000</velocity>
            <lower>-1e+16</lower>
            <upper>1e+16</upper>
          </limit>
          <dynamics>
            <spring_reference>0</spring_reference>
            <spring_stiffness>0</spring_stiffness>
          </dynamics>
        </axis>
      </joint>
      <link name='left_front_wheel'>
        <pose relative_to='left_front_wheel_joint'>0 0 0 0 -0 0</pose>
        <inertial>
          <pose>0 0 0 0 -0 0</pose>
          <mass>2</mass>
          <inertia>
            <ixx>0.664</ixx>
            <ixy>0</ixy>
            <ixz>0</ixz>
            <iyy>0.664</iyy>
            <iyz>0</iyz>
            <izz>1.02</izz>
          </inertia>
        </inertial>
        <collision name='left_front_wheel_collision'>
          <pose>0 0 0 1.57 -0 0</pose>
          <geometry>
            <cylinder>
              <length>0.2</length>
              <radius>0.32</radius>
            </cylinder>
          </geometry>
          <surface>
            <contact>
              <ode>
                <kp>100000</kp>
                <kd>5</kd>
              </ode>
            </contact>
            <friction>
              <ode>
                <mu>2</mu>
                <mu2>2</mu2>
                <fdir1>0 0 1</fdir1>
              </ode>
              <torsional>
                <ode/>
              </torsional>
            </friction>
            <bounce/>
          </surface>
          <max_contacts>10</max_contacts>
        </collision>
        <visual name='left_front_wheel_visual'>
          <pose>0 0 0 1.57 -0 0</pose>
          <geometry>
            <cylinder>
              <length>0.2</length>
              <radius>0.33</radius>
            </cylinder>
          </geometry>
          <material>
            <script>
              <name>Gazebo/Black</name>
              <uri>file://media/materials/scripts/gazebo.material</uri>
            </script>
          </material>
        </visual>
        <self_collide>0</self_collide>
        <enable_wind>0</enable_wind>
        <kinematic>0</kinematic>
      </link>
      <joint name='right_rear_wheel_joint' type='revolute'>
        <pose relative_to='base_footprint'>-1.3 -0.9 0.32 0 -0 0</pose>
        <parent>base_footprint</parent>
        <child>right_rear_wheel</child>
        <axis>
          <xyz>0 1 0</xyz>
          <limit>
            <effort>10</effort>
            <velocity>1000</velocity>
            <lower>-1e+16</lower>
            <upper>1e+16</upper>
          </limit>
          <dynamics>
            <spring_reference>0</spring_reference>
            <spring_stiffness>0</spring_stiffness>
          </dynamics>
        </axis>
      </joint>
      <link name='right_rear_wheel'>
        <pose relative_to='right_rear_wheel_joint'>0 0 0 0 -0 0</pose>
        <inertial>
          <pose>0 0 0 0 -0 0</pose>
          <mass>2</mass>
          <inertia>
            <ixx>0.664</ixx>
            <ixy>0</ixy>
            <ixz>0</ixz>
            <iyy>0.664</iyy>
            <iyz>0</iyz>
            <izz>1.02</izz>
          </inertia>
        </inertial>
        <collision name='right_rear_wheel_collision'>
          <pose>0 0 0 1.57 -0 0</pose>
          <geometry>
            <cylinder>
              <length>0.2</length>
              <radius>0.32</radius>
            </cylinder>
          </geometry>
          <surface>
            <contact>
              <ode>
                <kp>100000</kp>
                <kd>5</kd>
              </ode>
            </contact>
            <friction>
              <ode>
                <mu>2</mu>
                <mu2>2</mu2>
                <fdir1>1 0 0</fdir1>
              </ode>
              <torsional>
                <ode/>
              </torsional>
            </friction>
            <bounce/>
          </surface>
          <max_contacts>10</max_contacts>
        </collision>
        <visual name='right_rear_wheel_visual'>
          <pose>0 0 0 1.57 -0 0</pose>
          <geometry>
            <cylinder>
              <length>0.2</length>
              <radius>0.32</radius>
            </cylinder>
          </geometry>
          <material>
            <script>
              <name>Gazebo/Black</name>
              <uri>file://media/materials/scripts/gazebo.material</uri>
            </script>
          </material>
        </visual>
        <self_collide>0</self_collide>
        <enable_wind>0</enable_wind>
        <kinematic>0</kinematic>
      </link>
      <joint name='right_steering_hinge_joint' type='revolute'>
        <pose relative_to='base_footprint'>1.3 -0.65 0.32 0 -0 0</pose>
        <parent>base_footprint</parent>
        <child>right_steering_hinge</child>
        <axis>
          <xyz>0 0 1</xyz>
          <limit>
            <lower>-0.6</lower>
            <upper>0.6</upper>
            <effort>5</effort>
            <velocity>100</velocity>
          </limit>
          <dynamics>
            <spring_reference>0</spring_reference>
            <spring_stiffness>0</spring_stiffness>
          </dynamics>
        </axis>
      </joint>
      <link name='right_steering_hinge'>
        <pose relative_to='right_steering_hinge_joint'>0 0 0 0 -0 0</pose>
        <inertial>
          <pose>0 0 0 0 -0 0</pose>
          <mass>1</mass>
          <inertia>
            <ixx>0.027</ixx>
            <ixy>0</ixy>
            <ixz>0</ixz>
            <iyy>0.027</iyy>
            <iyz>0</iyz>
            <izz>0.05</izz>
          </inertia>
        </inertial>
        <collision name='right_steering_hinge_collision'>
          <pose>0 0 0 1.57 -0 0</pose>
          <geometry>
            <cylinder>
              <length>0.05</length>
              <radius>0.1</radius>
            </cylinder>
          </geometry>
          <surface>
            <contact>
              <ode>
                <kp>100000</kp>
                <kd>5</kd>
              </ode>
            </contact>
            <friction>
              <ode>
                <mu>1</mu>
                <mu2>1</mu2>
                <fdir1>1 0 0</fdir1>
              </ode>
              <torsional>
                <ode/>
              </torsional>
            </friction>
            <bounce/>
          </surface>
          <max_contacts>10</max_contacts>
        </collision>
        <visual name='right_steering_hinge_visual'>
          <pose>0 0 0 1.57 -0 0</pose>
          <geometry>
            <cylinder>
              <length>0.05</length>
              <radius>0.1</radius>
            </cylinder>
          </geometry>
          <material>
            <script>
              <name>Gazebo/Black</name>
              <uri>file://media/materials/scripts/gazebo.material</uri>
            </script>
          </material>
        </visual>
        <self_collide>0</self_collide>
        <enable_wind>0</enable_wind>
        <kinematic>0</kinematic>
      </link>
      <joint name='right_front_wheel_joint' type='revolute'>
        <pose relative_to='right_steering_hinge'>0 -0.25 0 0 -0 0</pose>
        <parent>right_steering_hinge</parent>
        <child>right_front_wheel</child>
        <axis>
          <xyz>0 1 0</xyz>
          <limit>
            <effort>10</effort>
            <velocity>1000</velocity>
            <lower>-1e+16</lower>
            <upper>1e+16</upper>
          </limit>
          <dynamics>
            <spring_reference>0</spring_reference>
            <spring_stiffness>0</spring_stiffness>
          </dynamics>
        </axis>
      </joint>
      <link name='right_front_wheel'>
        <pose relative_to='right_front_wheel_joint'>0 0 0 0 -0 0</pose>
        <inertial>
          <pose>0 0 0 0 -0 0</pose>
          <mass>2</mass>
          <inertia>
            <ixx>0.664</ixx>
            <ixy>0</ixy>
            <ixz>0</ixz>
            <iyy>0.664</iyy>
            <iyz>0</iyz>
            <izz>1.02</izz>
          </inertia>
        </inertial>
        <collision name='right_front_wheel_collision'>
          <pose>0 0 0 1.57 -0 0</pose>
          <geometry>
            <cylinder>
              <length>0.2</length>
              <radius>0.32</radius>
            </cylinder>
          </geometry>
          <surface>
            <contact>
              <ode>
                <kp>100000</kp>
                <kd>5</kd>
              </ode>
            </contact>
            <friction>
              <ode>
                <mu>2</mu>
                <mu2>2</mu2>
                <fdir1>0 0 1</fdir1>
              </ode>
              <torsional>
                <ode/>
              </torsional>
            </friction>
            <bounce/>
          </surface>
          <max_contacts>10</max_contacts>
        </collision>
        <visual name='right_front_wheel_visual'>
          <pose>0 0 0 1.57 -0 0</pose>
          <geometry>
            <cylinder>
              <length>0.2</length>
              <radius>0.33</radius>
            </cylinder>
          </geometry>
          <material>
            <script>
              <name>Gazebo/Black</name>
              <uri>file://media/materials/scripts/gazebo.material</uri>
            </script>
          </material>
        </visual>
        <self_collide>0</self_collide>
        <enable_wind>0</enable_wind>
        <kinematic>0</kinematic>
      </link>
      <plugin name='gazebo_ros_control' filename='libgazebo_ros_control.so'>
        <robotNamespace>/racecar</robotNamespace>
        <robotParam>robot_description</robotParam>
        <robotSimType>gazebo_ros_control/DefaultRobotHWSim</robotSimType>
      </plugin>
      <plugin name='joint_state_publisher' filename='libgazebo_ros_joint_state_publisher.so'>
        <jointName>right_rear_wheel_joint, left_rear_wheel_joint, right_front_wheel_joint, right_steering_hinge_joint, left_front_wheel_joint, left_steering_hinge_joint</jointName>
        <updateRate>50.0</updateRate>
        <robotNamespace>/racecar</robotNamespace>
        <alwaysOn>1</alwaysOn>
      </plugin>
      <frame name='base_link2base_footprint' attached_to='base_footprint'>
        <pose>0 0 0.32 0 -0 0</pose>
      </frame>
      <frame name='base_link' attached_to='base_link2base_footprint'/>
      <pose>0 0 0.02 0 0 -0.8</pose>
    </model>
    <state world_name='default'>
      <sim_time>155 837000000</sim_time>
      <real_time>156 359196411</real_time>
      <wall_time>1753724565 540180285</wall_time>
      <iterations>155837</iterations>
      <model name='ground_plane'>
        <pose>0 0 0 0 -0 0</pose>
        <scale>1 1 1</scale>
        <link name='link'>
          <pose>0 0 0 0 -0 0</pose>
          <velocity>0 0 0 0 -0 0</velocity>
          <acceleration>0 0 0 0 -0 0</acceleration>
          <wrench>0 0 0 0 -0 0</wrench>
        </link>
      </model>
      <model name='racecar'>
        <pose>58.8398 -74.8623 -0.00323 6.8e-05 0.002556 -1.25928</pose>
        <scale>1 1 1</scale>
        <link name='base_footprint'>
          <pose>58.8398 -74.8623 -0.00323 6.8e-05 0.002556 -1.25928</pose>
          <velocity>-0.004871 0.01345 -0.169271 0.007399 0.005412 -0.000283</velocity>
          <acceleration>0.022504 0.073789 -0.665051 -0.088839 0.16761 0.005037</acceleration>
          <wrench>0.090017 0.295155 -2.6602 0 -0 0</wrench>
        </link>
        <link name='left_front_wheel'>
          <pose>60.0104 -75.7036 0.313858 3.14002 -0.05792 2.48241</pose>
          <velocity>-0.004758 0.00883 -0.180418 -0.026343 -0.015426 -0.005299</velocity>
          <acceleration>0.019668 0.077466 -0.756073 -0.239097 0.058243 0.016298</acceleration>
          <wrench>0.039336 0.154932 -1.51215 0 -0 0</wrench>
        </link>
        <link name='left_rear_wheel'>
          <pose>59.2983 -73.3498 0.320153 0.000261 -1.30712 -1.25953</pose>
          <velocity>-0.002674 0.010892 -0.16056 0.007399 0.005413 -0.000284</velocity>
          <acceleration>0.011374 0.0777 -0.873453 -0.075098 0.095645 -0.003136</acceleration>
          <wrench>0.022748 0.1554 -1.7469 0 -0 0</wrench>
        </link>
        <link name='left_steering_hinge'>
          <pose>59.8572 -75.9013 0.31349 0.001589 0.002071 -0.659265</pose>
          <velocity>-0.004215 0.009937 -0.182449 -0.006877 0.016488 -0.006905</velocity>
          <acceleration>0.02571 0.07869 -0.721066 -0.210259 0.412381 0.016886</acceleration>
          <wrench>0.02571 0.07869 -0.721066 0 -0 0</wrench>
        </link>
        <link name='right_front_wheel'>
          <pose>58.3719 -76.2671 0.313653 -0.001154 0.314563 -1.70211</pose>
          <velocity>-0.001357 0.010059 -0.175745 -0.031607 -0.003207 0.005356</velocity>
          <acceleration>0.04043 0.077089 -0.461454 -0.240497 0.126016 0.003571</acceleration>
          <wrench>0.080861 0.154178 -0.922908 0 -0 0</wrench>
        </link>
        <link name='right_rear_wheel'>
          <pose>57.5849 -73.9015 0.32003 3.14147 -1.00535 1.88242</pose>
          <velocity>-0.002699 0.011481 -0.155367 0.007373 0.005493 -0.000203</velocity>
          <acceleration>0.031724 0.068375 -0.567533 -0.077308 0.102519 0.032988</acceleration>
          <wrench>0.063448 0.136749 -1.13506 0 -0 0</wrench>
        </link>
        <link name='right_steering_hinge'>
          <pose>58.6198 -76.2997 0.313402 -0.001008 0.002339 -1.70177</pose>
          <velocity>-0.003582 0.011247 -0.178726 0.008096 0.010632 0.00746</velocity>
          <acceleration>0.033297 0.071675 -0.499202 -0.031516 -0.04374 -0.016719</acceleration>
          <wrench>0.033297 0.071675 -0.499202 0 -0 0</wrench>
        </link>
      </model>
      <light name='sun'>
        <pose>0 0 10 0 -0 0</pose>
      </light>
    </state>
    <gui fullscreen='0'>
      <camera name='user_camera'>
        <pose>-74.6252 25.3426 103.299 -0 0.759643 -0.579806</pose>
        <view_controller>orbit</view_controller>
        <projection_type>perspective</projection_type>
      </camera>
    </gui>
  </world>
</sdf>
